# [На главную](https://github.com/xXxCLOTIxXx/python_couch)

В Python исключения — это механизм, который позволяет обрабатывать ошибки, возникающие во время выполнения программы. Вместо того чтобы программа завершилась аварийно, вы можете обработать ошибку и продолжить выполнение программы или сообщить пользователю о проблеме.
Обработка исключений

# 1) Обработка исключений в Python осуществляется с помощью конструкции try-except. Пример:

```python

try:
    # Код, который может вызвать исключение
    x = 10 / 0
except ZeroDivisionError:
    # Код, который выполнится, если произошло исключение ZeroDivisionError
    print("Деление на ноль невозможно!")
```
В этом примере, если попытка разделить на ноль приведет к возникновению исключения ZeroDivisionError, программа не завершится аварийно, а выполнится блок except, выводя сообщение о том, что деление на ноль невозможно.
Несколько блоков except

# 2) Вы можете обработать разные типы исключений с помощью нескольких блоков except:

```python

try:
    x = int(input("Введите число: "))
    y = 10 / x
except ZeroDivisionError:
    print("Ошибка: Деление на ноль!")
except ValueError:
    print("Ошибка: Введено не число!")
```
Если ввести некорректное значение (например, строку), будет выведено сообщение об ошибке ValueError. Если ввести 0, будет обработано исключение ZeroDivisionError.
# 3) Блок finally

Блок finally выполняется всегда, вне зависимости от того, было ли исключение или нет. Он используется для выполнения завершающих действий, например, закрытия файлов:

```python

try:
    file = open("file.txt", "r")
    # Работа с файлом
except FileNotFoundError:
    print("Файл не найден!")
finally:
    file.close()
```
# 4) Создание собственных исключений

Вы можете создавать свои собственные исключения, наследуя их от встроенного класса Exception. Это полезно, когда нужно сигнализировать о какой-то специфической для вашего приложения ошибке:

```python

class MyCustomError(Exception):
    pass

def test_func(x):
    if x < 0:
        raise MyCustomError("Отрицательное значение недопустимо!")

try:
    test_func(-5)
except MyCustomError as e:
    print(f"Произошла ошибка: {e}")
```
В этом примере при вызове test_func с отрицательным значением будет вызвано пользовательское исключение MyCustomError.
# 5) Блок else

Блок else в конструкции try-except выполняется только если исключение не произошло:

```python

try:
    result = 10 / 2
except ZeroDivisionError:
    print("Ошибка: Деление на ноль!")
else:
    print("Операция успешно выполнена:", result)
```
Здесь, если деление проходит успешно, блок else выполняется и выводит результат.
# 6) Обработка нескольких исключений в одном блоке except

Вы можете обрабатывать несколько типов исключений в одном блоке except:

```python

try:
    x = int(input("Введите число: "))
    y = 10 / x
except (ZeroDivisionError, ValueError):
    print("Произошла ошибка: либо деление на ноль, либо введено некорректное значение!")
```
# 7) Перехват всех исключений

Чтобы перехватить абсолютно все исключения, можно использовать except без указания типа исключения. Это не рекомендуется использовать без необходимости, так как может скрывать реальные ошибки:

```python

try:
    # Потенциально опасный код
    pass
except Exception as e:
    print(f"Произошла непредвиденная ошибка: {e}")
```
# Заключение

Исключения в Python предоставляют мощный механизм для управления ошибками и делают код более устойчивым и безопасным. Важно понимать, как правильно использовать и обрабатывать исключения, чтобы ваш код мог справляться с неожиданными ситуациями.
